2023-04-15 17:45:36,695 [INFO] Staring Flask WiFix DB server
2023-04-15 17:45:36,695 [INFO] Creating tables (if not exist)
2023-04-15 17:45:38,234 [INFO] Creating wifi_session_cleanup event
2023-04-15 17:45:38,499 [INFO] Cron - updating wifi speeds for company: bar_test
2023-04-15 17:46:11,165 [INFO] Staring Flask WiFix DB server
2023-04-15 17:46:11,165 [INFO] Creating tables (if not exist)
2023-04-15 17:46:12,647 [INFO] Creating wifi_session_cleanup event
2023-04-15 17:46:12,909 [INFO] Cron - updating wifi speeds for company: bar_test
2023-04-15 17:46:39,389 [INFO] Staring Flask WiFix DB server
2023-04-15 17:46:39,390 [INFO] Creating tables (if not exist)
2023-04-15 17:46:40,885 [INFO] Creating wifi_session_cleanup event
2023-04-15 17:46:41,143 [INFO] Cron - updating wifi speeds for company: bar_test
2023-04-15 17:48:13,449 [INFO] Staring Flask WiFix DB server
2023-04-15 17:48:13,449 [INFO] Creating tables (if not exist)
2023-04-15 17:48:15,079 [INFO] Creating wifi_session_cleanup event
2023-04-15 17:48:15,298 [INFO] Cron - updating wifi speeds for company: bar_test
2023-04-15 17:48:49,305 [INFO] Staring Flask WiFix DB server
2023-04-15 17:48:49,305 [INFO] Creating tables (if not exist)
2023-04-15 17:48:50,810 [INFO] Creating wifi_session_cleanup event
2023-04-15 17:48:51,026 [INFO] Cron - updating wifi speeds for company: bar_test
2023-04-15 17:49:14,780 [INFO] Staring Flask WiFix DB server
2023-04-15 17:49:14,781 [INFO] Creating tables (if not exist)
2023-04-15 17:49:16,292 [INFO] Creating wifi_session_cleanup event
2023-04-15 17:49:16,562 [INFO] Cron - updating wifi speeds for company: bar_test
2023-04-15 17:49:54,906 [INFO] Staring Flask WiFix DB server
2023-04-15 17:49:54,906 [INFO] Creating tables (if not exist)
2023-04-15 17:49:56,464 [INFO] Creating wifi_session_cleanup event
2023-04-15 17:49:56,683 [INFO] Cron - updating wifi speeds for company: bar_test
2023-04-15 17:50:02,925 [ERROR] The string is not in the correct format.
Traceback (most recent call last):
  File "/Users/bar.sela/PycharmProjects/Wifix-github/backend/db_server/validation.py", line 73, in validate_datetime
    datetime.strptime(str_date, Const.DATE_FORMAT)
  File "/Library/Developer/CommandLineTools/Library/Frameworks/Python3.framework/Versions/3.9/lib/python3.9/_strptime.py", line 568, in _strptime_datetime
    tt, fraction, gmtoff_fraction = _strptime(data_string, format)
  File "/Library/Developer/CommandLineTools/Library/Frameworks/Python3.framework/Versions/3.9/lib/python3.9/_strptime.py", line 349, in _strptime
    raise ValueError("time data %r does not match format %r" %
ValueError: time data '2023-04-10' does not match format '%d/%m/%Y'

During handling of the above exception, another exception occurred:

Traceback (most recent call last):
  File "/Users/bar.sela/PycharmProjects/Wifix-github/env2/lib/python3.9/site-packages/flask/app.py", line 1823, in full_dispatch_request
    rv = self.dispatch_request()
  File "/Users/bar.sela/PycharmProjects/Wifix-github/env2/lib/python3.9/site-packages/flask/app.py", line 1799, in dispatch_request
    return self.ensure_sync(self.view_functions[rule.endpoint])(**view_args)
  File "/Users/bar.sela/PycharmProjects/Wifix-github/backend/db_server/app.py", line 132, in admin_get_current_balance
    response = admin.get_current_balance(data)
  File "/Users/bar.sela/PycharmProjects/Wifix-github/backend/db_server/endpoints/admin_endpoints/endpoints.py", line 66, in get_current_balance
    validate_datetime(from_date)
  File "/Users/bar.sela/PycharmProjects/Wifix-github/backend/db_server/validation.py", line 75, in validate_datetime
    raise Exception("The string is not in the correct format.")
Exception: The string is not in the correct format.
2023-04-15 17:50:25,519 [ERROR] The string is not in the correct format.
Traceback (most recent call last):
  File "/Users/bar.sela/PycharmProjects/Wifix-github/backend/db_server/validation.py", line 73, in validate_datetime
    datetime.strptime(str_date, Const.DATE_FORMAT)
  File "/Library/Developer/CommandLineTools/Library/Frameworks/Python3.framework/Versions/3.9/lib/python3.9/_strptime.py", line 568, in _strptime_datetime
    tt, fraction, gmtoff_fraction = _strptime(data_string, format)
  File "/Library/Developer/CommandLineTools/Library/Frameworks/Python3.framework/Versions/3.9/lib/python3.9/_strptime.py", line 349, in _strptime
    raise ValueError("time data %r does not match format %r" %
ValueError: time data '2023-04-10' does not match format '%d/%m/%Y'

During handling of the above exception, another exception occurred:

Traceback (most recent call last):
  File "/Users/bar.sela/PycharmProjects/Wifix-github/env2/lib/python3.9/site-packages/flask/app.py", line 1823, in full_dispatch_request
    rv = self.dispatch_request()
  File "/Users/bar.sela/PycharmProjects/Wifix-github/env2/lib/python3.9/site-packages/flask/app.py", line 1799, in dispatch_request
    return self.ensure_sync(self.view_functions[rule.endpoint])(**view_args)
  File "/Users/bar.sela/PycharmProjects/Wifix-github/backend/db_server/app.py", line 132, in admin_get_current_balance
    response = admin.get_current_balance(data)
  File "/Users/bar.sela/PycharmProjects/Wifix-github/backend/db_server/endpoints/admin_endpoints/endpoints.py", line 66, in get_current_balance
    validate_datetime(from_date)
  File "/Users/bar.sela/PycharmProjects/Wifix-github/backend/db_server/validation.py", line 75, in validate_datetime
    raise Exception("The string is not in the correct format.")
Exception: The string is not in the correct format.
2023-04-15 17:50:52,404 [INFO] Staring Flask WiFix DB server
2023-04-15 17:50:52,404 [INFO] Creating tables (if not exist)
2023-04-15 17:50:54,611 [INFO] Staring Flask WiFix DB server
2023-04-15 17:50:54,611 [INFO] Creating tables (if not exist)
2023-04-15 17:50:56,131 [INFO] Creating wifi_session_cleanup event
2023-04-15 17:50:56,409 [INFO] Cron - updating wifi speeds for company: bar_test
2023-04-15 17:52:19,466 [ERROR] The string is not in the correct format.
Traceback (most recent call last):
  File "/Users/bar.sela/PycharmProjects/Wifix-github/backend/db_server/validation.py", line 73, in validate_datetime
    datetime.strptime(str_date, Const.DATE_FORMAT)
  File "/Library/Developer/CommandLineTools/Library/Frameworks/Python3.framework/Versions/3.9/lib/python3.9/_strptime.py", line 568, in _strptime_datetime
    tt, fraction, gmtoff_fraction = _strptime(data_string, format)
  File "/Library/Developer/CommandLineTools/Library/Frameworks/Python3.framework/Versions/3.9/lib/python3.9/_strptime.py", line 349, in _strptime
    raise ValueError("time data %r does not match format %r" %
ValueError: time data '2023-04-10' does not match format '%d/%m/%Y'

During handling of the above exception, another exception occurred:

Traceback (most recent call last):
  File "/Users/bar.sela/PycharmProjects/Wifix-github/env2/lib/python3.9/site-packages/flask/app.py", line 1823, in full_dispatch_request
    rv = self.dispatch_request()
  File "/Users/bar.sela/PycharmProjects/Wifix-github/env2/lib/python3.9/site-packages/flask/app.py", line 1799, in dispatch_request
    return self.ensure_sync(self.view_functions[rule.endpoint])(**view_args)
  File "/Users/bar.sela/PycharmProjects/Wifix-github/backend/db_server/app.py", line 132, in admin_get_current_balance
    response = admin.get_current_balance(data)
  File "/Users/bar.sela/PycharmProjects/Wifix-github/backend/db_server/endpoints/admin_endpoints/endpoints.py", line 66, in get_current_balance
    validate_datetime(from_date)
  File "/Users/bar.sela/PycharmProjects/Wifix-github/backend/db_server/validation.py", line 75, in validate_datetime
    raise Exception("The string is not in the correct format.")
Exception: The string is not in the correct format.
2023-04-15 17:52:19,483 [ERROR] The string is not in the correct format.
Traceback (most recent call last):
  File "/Users/bar.sela/PycharmProjects/Wifix-github/backend/db_server/validation.py", line 73, in validate_datetime
    datetime.strptime(str_date, Const.DATE_FORMAT)
  File "/Library/Developer/CommandLineTools/Library/Frameworks/Python3.framework/Versions/3.9/lib/python3.9/_strptime.py", line 568, in _strptime_datetime
    tt, fraction, gmtoff_fraction = _strptime(data_string, format)
  File "/Library/Developer/CommandLineTools/Library/Frameworks/Python3.framework/Versions/3.9/lib/python3.9/_strptime.py", line 349, in _strptime
    raise ValueError("time data %r does not match format %r" %
ValueError: time data '2023-04-10' does not match format '%d/%m/%Y'

During handling of the above exception, another exception occurred:

Traceback (most recent call last):
  File "/Users/bar.sela/PycharmProjects/Wifix-github/env2/lib/python3.9/site-packages/flask/app.py", line 1823, in full_dispatch_request
    rv = self.dispatch_request()
  File "/Users/bar.sela/PycharmProjects/Wifix-github/env2/lib/python3.9/site-packages/flask/app.py", line 1799, in dispatch_request
    return self.ensure_sync(self.view_functions[rule.endpoint])(**view_args)
  File "/Users/bar.sela/PycharmProjects/Wifix-github/backend/db_server/app.py", line 132, in admin_get_current_balance
    response = admin.get_current_balance(data)
  File "/Users/bar.sela/PycharmProjects/Wifix-github/backend/db_server/endpoints/admin_endpoints/endpoints.py", line 66, in get_current_balance
    validate_datetime(from_date)
  File "/Users/bar.sela/PycharmProjects/Wifix-github/backend/db_server/validation.py", line 75, in validate_datetime
    raise Exception("The string is not in the correct format.")
Exception: The string is not in the correct format.
2023-04-15 17:55:57,390 [INFO] Cron - updating wifi speeds for company: bar_test
